Workbook

Sheet Ações
A1: Ticker | B1: Nome | C1: CNPJ | D1: Segmento | E1: Setor
A2: AALR3 | B2: ALLIANÇA SAÚDE E PARTICIPAÇÕES S.A. | C2: 42.771.949/0001-35 | D2: Serv.Méd.Hospit..Análises e Diagnósticos | E2: Saúde
A3: ABCB4 | B3: BCO ABC BRASIL S.A. | C3: 28.195.667/0001-06 | D3: Bancos | E3: Financeiro
A4: ABEV3 | B4: AMBEV S.A. | C4: 07.526.557/0001-00 | D4: Cervejas e Refrigerantes | E4: Consumo não Cíclico
A5: ADMF3 | B5: CIABRASF CIA BRASILEIRA DE SERVIÇOS FINANCEIROS SA | C5: 52.270.350/0001-71 | D5: Serviços Diversos | E5: Financeiro
A6: AERI3 | B6: AERIS IND. E COM. DE EQUIP. GERACAO DE ENERGIA S/A | C6: 12.528.708/0001-07 | D6: Máq. e Equip. Industriais | E6: Bens Industriais
A7: AESB3 | B7: AUREN PARTICIPAÇÕES S.A. | C7: 37.663.076/0001-07 | D7: Energia Elétrica | E7: Utilidade Pública
A8: AFLT3 | B8: AFLUENTE TRANSMISSÃO DE ENERGIA ELÉTRICA S/A | C8: 10.338.320/0001-00 | D8: Energia Elétrica | E8: Utilidade Pública
A9: AGRO3 | B9: BRASILAGRO - CIA BRAS DE PROP AGRICOLAS | C9: 07.628.528/0001-59 | D9: Agricultura | E9: Consumo não Cíclico
A10: AGXY3 | B10: AGROGALAXY PARTICIPAÇÕES S.A. | C10: 21.240.146/0001-84 | D10: Agricultura | E10: Consumo não Cíclico
A11: AHEB3 | B11: SAO PAULO TURISMO S.A. | C11: 62.002.886/0001-60 | D11: Produção de Eventos e Shows | E11: Consumo Cíclico
A12: AHEB5 | B12: SAO PAULO TURISMO S.A. | C12: 62.002.886/0001-60 | D12: Produção de Eventos e Shows | E12: Consumo Cíclico
... A260: INEP4 | B260: INEPAR S.A. INDUSTRIA E CONSTRUCOES | C260: 76.627.504/0001-06 | D260: Máq. e Equip. Industriais | E260: Bens Industriais
A261: INTB3 | B261: INTELBRAS S.A. IND DE TELEC ELETRONICA BRASILEIRA
A262: IRBR3 | B262: IRB - BRASIL RESSEGUROS S.A. | C262: 33.376.989/0001-91 | D262: Resseguradoras | E262: Financeiro
A263: ISAE3 | B263: ISA ENERGIA BRASIL S.A | C263: 02.998.611/0001-04 | D263: Energia Elétrica | E263: Utilidade Pública
A264: ISAE4 | B264: ISA ENERGIA BRASIL S.A | C264: 02.998.611/0001-04 | D264: Energia Elétrica | E264: Utilidade Pública
A265: ITSA3 | B265: ITAUSA S.A. | C265: 61.532.644/0001-15 | D265: Holdings Diversificadas | E265: Financeiro
A266: ITSA4 | B266: ITAUSA S.A. | C266: 61.532.644/0001-15 | D266: Holdings Diversificadas | E266: Financeiro
A267: ITUB3 | B267: ITAU UNIBANCO HOLDING S.A. | C267: 60.872.504/0001-23 | D267: Bancos | E267: Financeiro
A268: ITUB4 | B268: ITAU UNIBANCO HOLDING S.A. | C268: 60.872.504/0001-23 | D268: Bancos | E268: Financeiro
A269: JALL3 | B269: JALLES MACHADO S.A. | C269: 02.635.522/0001-95 | D269: Açucar e Alcool | E269: Consumo não Cíclico
A270: JFEN3 | B270: JOAO FORTES ENGENHARIA S.A. | C270: 33.035.536/0001-00 | D270: Incorporações | E270: Consumo Cíclico
A271: JHSF3 | B271: JHSF PARTICIPACOES S.A. | C271: 08.294.224/0001-65 | D271: Incorporações | E271: Consumo Cíclico
A272: JOPA3 | B272: JOSAPAR-JOAQUIM OLIVEIRA S.A. - PARTICIP | C272: 87.456.562/0001-22 | D272: Alimentos Diversos | E272: Consumo não Cíclico
A273: JOPA4 | B273: JOSAPAR-JOAQUIM OLIVEIRA S.A. - PARTICIP | C273: 87.456.562/0001-22 | D273: Alimentos Diversos | E273: Consumo não Cíclico
... A398: RPMG3 | B398: REFINARIA DE PETROLEOS MANGUINHOS S.A. | C398: 33.412.081/0001-96 | D398: Exploração. Refino e Distribuição | E398: Petróleo. Gás e Biocombustíveis
A399: RRRP3 | B399: 3R PETROLEUM ÓLEO E GÁS S.A
A400: RSID3 | B400: ROSSI RESIDENCIAL S.A. | C400: 61.065.751/0001-80 | D400: Incorporações | E400: Consumo Cíclico
A401: RSUL4 | B401: METALURGICA RIOSULENSE S.A. | C401: 85.778.074/0001-06 | D401: Material Rodoviário | E401: Bens Industriais
A402: RVEE3 | B402: REVEE S.A. | C402: 52.841.191/0001-18 | D402: Produção de Eventos e Shows | E402: Consumo Cíclico
A403: SANB11 | B403: BCO SANTANDER (BRASIL) S.A. | C403: 90.400.888/0001-42 | D403: Bancos | E403: Financeiro
A404: SANB3 | B404: BCO SANTANDER (BRASIL) S.A. | C404: 90.400.888/0001-42 | D404: Bancos | E404: Financeiro
A405: SANB4 | B405: BCO SANTANDER (BRASIL) S.A. | C405: 90.400.888/0001-42 | D405: Bancos | E405: Financeiro
A406: SAPR11 | B406: CIA SANEAMENTO DO PARANA - SANEPAR | C406: 76.484.013/0001-45 | D406: Água e Saneamento | E406: Utilidade Pública
A407: SAPR3 | B407: CIA SANEAMENTO DO PARANA - SANEPAR | C407: 76.484.013/0001-45 | D407: Água e Saneamento | E407: Utilidade Pública
A408: SAPR4 | B408: CIA SANEAMENTO DO PARANA - SANEPAR | C408: 76.484.013/0001-45 | D408: Água e Saneamento | E408: Utilidade Pública
A409: SBFG3 | B409: GRUPO SBF SA | C409: 13.217.485/0001-11 | D409: Produtos Diversos | E409: Consumo Cíclico
A410: SBSP3 | B410: CIA SANEAMENTO BASICO EST SAO PAULO | C410: 43.776.517/0001-80 | D410: Água e Saneamento | E410: Utilidade Pública
A411: SCAR3 | B411: SAO CARLOS EMPREEND E PARTICIPACOES S.A. | C411: 29.780.061/0001-09 | D411: Exploração de Imóveis | E411: Financeiro
...

Sheet FIIs
A1: Ticker | B1: Nome | C1: CNPJ | D1: Tipo de Fundo | E1: Segmento
A2: ABCP11 | B2: FDO INV IMOB GRAND PLAZA SHOPPING | C2: 01.201.140/0001-90 | D2: =IFERROR(VLOOKUP(A2,base_fiis_inv10!$A$1:$C$282,2,FALSE),"Não encontrado") -> Não encontrado | E2: =IFERROR(VLOOKUP(A2,base_fiis_inv10!$A$1:$C$282,3,FALSE),"Não encontrado") -> Não encontrado
A3: AFHI11 | B3: AF INVEST CRI FDO. INV. IMOB - RECEBÍVEIS IMOB. | C3: 36.642.293/0001-58 | D3: =IFERROR(VLOOKUP(A3,base_fiis_inv10!$A$1:$C$282,2,FALSE),"Não encontrado") -> Fundo de papel | E3: =IFERROR(VLOOKUP(A3,base_fiis_inv10!$A$1:$C$282,3,FALSE),"Não encontrado") -> Títulos e Valores Mobiliários
A4: AIEC11 | B4: AUTONOMY EDIFÍCIOS CORPORATIVOS FUND. INV. IMOB. | C4: 35.765.826/0001-26 | D4: =IFERROR(VLOOKUP(A4,base_fiis_inv10!$A$1:$C$282,2,FALSE),"Não encontrado") -> Fundo de Tijolo | E4: =IFERROR(VLOOKUP(A4,base_fiis_inv10!$A$1:$C$282,3,FALSE),"Não encontrado") -> Lajes Corporativas
A5: AJFI11 | B5: AJ MALLS FDO DE INV IMOB | C5: 51.472.985/0001-99 | D5: =IFERROR(VLOOKUP(A5,base_fiis_inv10!$A$1:$C$282,2,FALSE),"Não encontrado") -> Fundo de Tijolo | E5: =IFERROR(VLOOKUP(A5,base_fiis_inv10!$A$1:$C$282,3,FALSE),"Não encontrado") -> Shoppings / Varejo
A6: ALMI11 | B6: FDO INV IMOB - FII TORRE ALMIRANTE | C6: 07.122.725/0001-00 | D6: =IFERROR(VLOOKUP(A6,base_fiis_inv10!$A$1:$C$282,2,FALSE),"Não encontrado") -> Não encontrado | E6: =IFERROR(VLOOKUP(A6,base_fiis_inv10!$A$1:$C$282,3,FALSE),"Não encontrado") -> Não encontrado
A7: ALZC11 | B7: ALIANZA CRÉDITO IMOBILIÁRIO FUNDO DE INVESTIMENTO | C7: 40.011.324/0001-40 | D7: =IFERROR(VLOOKUP(A7,base_fiis_inv10!$A$1:$C$282,2,FALSE),"Não encontrado") -> Fundo de papel | E7: =IFERROR(VLOOKUP(A7,base_fiis_inv10!$A$1:$C$282,3,FALSE),"Não encontrado") -> Títulos e Valores Mobiliários
A8: ALZM11 | B8: ALIANZA MULTIESTRATÉGIA FUNDO DE INVESTIMENTO IMOB | C8: 34.847.063/0001-08 | D8: =IFERROR(VLOOKUP(A8,base_fiis_inv10!$A$1:$C$282,2,FALSE),"Não encontrado") -> Fundo de fundos | E8: =IFERROR(VLOOKUP(A8,base_fiis_inv10!$A$1:$C$282,3,FALSE),"Não encontrado") -> Títulos e Valores Mobiliários
A9: ALZR11 | B9: ALIANZA TRUST RENDA IMOBILIARIA FDO INV IMOB | C9: 28.737.771/0001-85 | D9: =IFERROR(VLOOKUP(A9,base_fiis_inv10!$A$1:$C$282,2,FALSE),"Não encontrado") -> Fundo de Tijolo | E9: =IFERROR(VLOOKUP(A9,base_fiis_inv10!$A$1:$C$282,3,FALSE),"Não encontrado") -> Híbrido
A10: ANCR11 | B10: FDO INV IMOB - FII ANCAR IC | C10: 07.789.135/0001-27 | D10: =IFERROR(VLOOKUP(A10,base_fiis_inv10!$A$1:$C$282,2,FALSE),"Não encontrado") -> Não encontrado | E10: =IFERROR(VLOOKUP(A10,base_fiis_inv10!$A$1:$C$282,3,FALSE),"Não encontrado") -> Não encontrado
A11: APTO11 | B11: NAVI RESIDENCIAL FUNDO DE INVESTIMENTO IMOBILIÁRIO | C11: 42.432.327/0001-82 | D11: =IFERROR(VLOOKUP(A11,base_fiis_inv10!$A$1:$C$282,2,FALSE),"Não encontrado") -> Não encontrado | E11: =IFERROR(VLOOKUP(A11,base_fiis_inv10!$A$1:$C$282,3,FALSE),"Não encontrado") -> Não encontrado
A12: APXM11 | B12: FUNDO DE INVESTIMENTO IMOBILIÁRIO APEX MALLS - FII | C12: 43.010.485/0001-07 | D12: =IFERROR(VLOOKUP(A12,base_fiis_inv10!$A$1:$C$282,2,FALSE),"Não encontrado") -> Fundo de Tijolo | E12: =IFERROR(VLOOKUP(A12,base_fiis_inv10!$A$1:$C$282,3,FALSE),"Não encontrado") -> Shoppings / Varejo
A13: APXR11 | B13: APEX REALTY FDO DE INV IMOB RESP LTDA | C13: 52.446.271/0001-79 | D13: =IFERROR(VLOOKUP(A13,base_fiis_inv10!$A$1:$C$282,2,FALSE),"Não encontrado") -> Não encontrado | E13: =IFERROR(VLOOKUP(A13,base_fiis_inv10!$A$1:$C$282,3,FALSE),"Não encontrado") -> Não encontrado
... A405: ZIFI11 | B405: ZION CAPITAL FUNDO DE INVESTIMENTO IMOBILIÁRIO FII | C405: 35.820.768/0001-96 | D405: =IFERROR(VLOOKUP(A405,base_fiis_inv10!$A$1:$C$282,2,FALSE),"Não encontrado") -> Não encontrado | E405: =IFERROR(VLOOKUP(A405,base_fiis_inv10!$A$1:$C$282,3,FALSE),"Não encontrado") -> Não encontrado

Sheet FIAgros
A1: Ticker | B1: Nome | C1: CNPJ | D1: Tipo de Fundo | E1: Segmento Inv. 10 | F1: Segmento
A2: AAGR11 | B2: ASSET BANK AGRONEGÓCIOS FIAGRO -DC | C2: 44.585.001/0001-10 | D2: =IFERROR(VLOOKUP(A2,base_fiis_inv10!$A$1:$C$282,2,FALSE),"Não encontrado") -> Não encontrado | E2: =IFERROR(VLOOKUP(A2,base_fiis_inv10!$A$1:$C$282,3,FALSE),"Não encontrado") -> Não encontrado | F2: FIAgro
A3: AAZQ11 | B3: AZ QUEST SOLE FDO DE INV - FIAGRO - IMOB RESP LIM | C3: 44.625.826/0001-11 | D3: =IFERROR(VLOOKUP(A3,base_fiis_inv10!$A$1:$C$282,2,FALSE),"Não encontrado") -> Outro | E3: =IFERROR(VLOOKUP(A3,base_fiis_inv10!$A$1:$C$282,3,FALSE),"Não encontrado") -> Fiagros | F3: FIAgro
A4: AGRX11 | B4: FDO INV CAD PRO AGRO EXES ARAGUAIA – FIAGRO IMOB | C4: 43.951.911/0001-07 | D4: =IFERROR(VLOOKUP(A4,base_fiis_inv10!$A$1:$C$282,2,FALSE),"Não encontrado") -> Outro | E4: =IFERROR(VLOOKUP(A4,base_fiis_inv10!$A$1:$C$282,3,FALSE),"Não encontrado") -> Fiagros | F4: FIAgro
A5: BRFT11 | B5: BRADESCO FARMTECH FIDC DC RESP LIMITADA | C5: 52.512.069/0001-06 | D5: =IFERROR(VLOOKUP(A5,base_fiis_inv10!$A$1:$C$282,2,FALSE),"Não encontrado") -> Não encontrado | E5: =IFERROR(VLOOKUP(A5,base_fiis_inv10!$A$1:$C$282,3,FALSE),"Não encontrado") -> Não encontrado | F5: FIAgro
A6: CPTR11 | B6: CAPITANIA AGRO STRATEGIES – FIAGRO – IMOB RESP LIM | C6: 42.537.579/0001-76 | D6: =IFERROR(VLOOKUP(A6,base_fiis_inv10!$A$1:$C$282,2,FALSE),"Não encontrado") -> Outro | E6: =IFERROR(VLOOKUP(A6,base_fiis_inv10!$A$1:$C$282,3,FALSE),"Não encontrado") -> Fiagros | F6: FIAgro
A7: CPTR12 | B7: CAPITANIA AGRO STRATEGIES - FIAGRO - IMOBILIÁRIO | C7: 42.537.579/0001-76 | D7: =IFERROR(VLOOKUP(A7,base_fiis_inv10!$A$1:$C$282,2,FALSE),"Não encontrado") -> Não encontrado | E7: =IFERROR(VLOOKUP(A7,base_fiis_inv10!$A$1:$C$282,3,FALSE),"Não encontrado") -> Não encontrado | F7: FIAgro
A8: CRAA11 | B8: SPARTA FIAGRO FDO INV NAS CAD PROD AGRO RESP LIM | C8: 48.903.610/0001-21 | D8: =IFERROR(VLOOKUP(A8,base_fiis_inv10!$A$1:$C$282,2,FALSE),"Não encontrado") -> Outro | E8: =IFERROR(VLOOKUP(A8,base_fiis_inv10!$A$1:$C$282,3,FALSE),"Não encontrado") -> Fiagros | F8: FIAgro
A9: CTEM11 | B9: CAETÊ FIAGRO - FI NAS CAD PROD DO AGRO | C9: 50.749.446/0001-91 | D9: =IFERROR(VLOOKUP(A9,base_fiis_inv10!$A$1:$C$282,2,FALSE),"Não encontrado") -> Não encontrado | E9: =IFERROR(VLOOKUP(A9,base_fiis_inv10!$A$1:$C$282,3,FALSE),"Não encontrado") -> Não encontrado | F9: FIAgro
A10: DCRA11 | B10: DEVANT FDO INV NAS CAD PROD AGRONEGOCIO | C10: 42.888.360/0001-11 | D10: =IFERROR(VLOOKUP(A10,base_fiis_inv10!$A$1:$C$282,2,FALSE),"Não encontrado") -> Não encontrado | E10: =IFERROR(VLOOKUP(A10,base_fiis_inv10!$A$1:$C$282,3,FALSE),"Não encontrado") -> Não encontrado | F10: FIAgro
A11: EGAF11 | B11: ECOAGRO I FIAGRO – RESPONSABILIDADE LIMITADA | C11: 41.224.330/0001-48 | D11: =IFERROR(VLOOKUP(A11,base_fiis_inv10!$A$1:$C$282,2,FALSE),"Não encontrado") -> Outro | E11: =IFERROR(VLOOKUP(A11,base_fiis_inv10!$A$1:$C$282,3,FALSE),"Não encontrado") -> Fiagros | F11: FIAgro
A12: FGAA11 | B12: FG/AGRO FDO DE INVEST - FIAGRO - IMOB RESP LIM | C12: 42.405.905/0001-91 | D12: =IFERROR(VLOOKUP(A12,base_fiis_inv10!$A$1:$C$282,2,FALSE),"Não encontrado") -> Outro | E12: =IFERROR(VLOOKUP(A12,base_fiis_inv10!$A$1:$C$282,3,FALSE),"Não encontrado") -> Fiagros | F12: FIAgro
A13: FTCA11 | B13: FYTO RECEBÍVEIS DO AGRO - FIAGRO IMOB RESP LIM | C13: 42.537.438/0001-53 | D13: =IFERROR(VLOOKUP(A13,base_fiis_inv10!$A$1:$C$282,2,FALSE),"Não encontrado") -> Outro | E13: =IFERROR(VLOOKUP(A13,base_fiis_inv10!$A$1:$C$282,3,FALSE),"Não encontrado") -> Fiagros | F13: FIAgro
... A42: XPCA11 | B42: XP CRÉDITO AGRÍCOLA FI FIAGRO IMOB RESP LIM | C42: 41.269.527/0001-01 | D42: =IFERROR(VLOOKUP(A42,base_fiis_inv10!$A$1:$C$282,2,FALSE),"Não encontrado") -> Outro | E42: =IFERROR(VLOOKUP(A42,base_fiis_inv10!$A$1:$C$282,3,FALSE),"Não encontrado") -> Fiagros | F42: FIAgro

Sheet FIInfras
A1: Ticker | B1: Nome | C1: CNPJ | D1: Tipo de Fundo | E1: Segmento Inv. 10 | F1: Segmento
A2: BDIF11 | B2: BTG PACTUAL DÍVIDA INFRA FIC. FDO. INC. IE. RF. CP | C2: 40.502.607/0001-94 | D2: =IFERROR(VLOOKUP(A2,base_fiis_inv10!$A$1:$C$282,2,FALSE),"Não encontrado") -> Outro | E2: =IFERROR(VLOOKUP(A2,base_fiis_inv10!$A$1:$C$282,3,FALSE),"Não encontrado") -> Fundo de Infraestrutura (FI-Infra) | F2: FIInfra
A3: BIDB11 | B3: INTER INFRA FIC INFRA RENDA FIXA CRÉDITO PRIVADO | C3: 42.294.971/0001-31 | D3: =IFERROR(VLOOKUP(A3,base_fiis_inv10!$A$1:$C$282,2,FALSE),"Não encontrado") -> Outro | E3: =IFERROR(VLOOKUP(A3,base_fiis_inv10!$A$1:$C$282,3,FALSE),"Não encontrado") -> Fundo de Infraestrutura (FI-Infra) | F3: FIInfra
A4: BINC11 | B4: BRADESCO FIC DE FI FIN RF INV IE CDI RF CP RES LIM | C4: 55.239.865/0001-05 | D4: =IFERROR(VLOOKUP(A4,base_fiis_inv10!$A$1:$C$282,2,FALSE),"Não encontrado") -> Outro | E4: =IFERROR(VLOOKUP(A4,base_fiis_inv10!$A$1:$C$282,3,FALSE),"Não encontrado") -> Fundo de Infraestrutura (FI-Infra) | F4: FIInfra
A5: BODB11 | B5: BOCAINA INFRA - FDO INV COTAS FDO INV INFRA RF CP | C5: 41.771.670/0001-99 | D5: =IFERROR(VLOOKUP(A5,base_fiis_inv10!$A$1:$C$282,2,FALSE),"Não encontrado") -> Outro | E5: =IFERROR(VLOOKUP(A5,base_fiis_inv10!$A$1:$C$282,3,FALSE),"Não encontrado") -> Fundo de Infraestrutura (FI-Infra) | F5: FIInfra
A6: CDII11 | B6: SPARTA INFRA CDI FIC FI INFRA RENDA FIXA CP | C6: 48.973.783/0001-16 | D6: =IFERROR(VLOOKUP(A6,base_fiis_inv10!$A$1:$C$282,2,FALSE),"Não encontrado") -> Outro | E6: =IFERROR(VLOOKUP(A6,base_fiis_inv10!$A$1:$C$282,3,FALSE),"Não encontrado") -> Fundo de Infraestrutura (FI-Infra) | F6: FIInfra
A7: CPTI11 | B7: CAPITÂNIA FDO. INV. FINANCEIRO IE. RF. | C7: 38.065.012/0001-77 | D7: =IFERROR(VLOOKUP(A7,base_fiis_inv10!$A$1:$C$282,2,FALSE),"Não encontrado") -> Outro | E7: =IFERROR(VLOOKUP(A7,base_fiis_inv10!$A$1:$C$282,3,FALSE),"Não encontrado") -> Fundo de Infraestrutura (FI-Infra) | F7: FIInfra
A8: DBIN11 | B8: RB INFRA FI FIC RENDA FIXA RES LTDA | C8: 55.826.668/0001-84 | D8: =IFERROR(VLOOKUP(A8,base_fiis_inv10!$A$1:$C$282,2,FALSE),"Não encontrado") -> Não encontrado | E8: =IFERROR(VLOOKUP(A8,base_fiis_inv10!$A$1:$C$282,3,FALSE),"Não encontrado") -> Não encontrado | F8: FIInfra
A9: DIVS11 | B9: SPARTA INFRA INFLAÇÃO LONGA FI COTAS FI INFRA E RE | C9: 58.390.457/0001-30 | D9: =IFERROR(VLOOKUP(A9,base_fiis_inv10!$A$1:$C$282,2,FALSE),"Não encontrado") -> Fundo de desenvolvimento | E9: =IFERROR(VLOOKUP(A9,base_fiis_inv10!$A$1:$C$282,3,FALSE),"Não encontrado") -> Fundo de Infraestrutura (FI-Infra) | F9: FIInfra
A10: EXIF11 | B10: ÉXES FIC FI INFRA RENDA FIXA PRIVADO LONGO PRAZO | C10: 54.803.944/0001-26 | D10: =IFERROR(VLOOKUP(A10,base_fiis_inv10!$A$1:$C$282,2,FALSE),"Não encontrado") -> Não encontrado | E10: =IFERROR(VLOOKUP(A10,base_fiis_inv10!$A$1:$C$282,3,FALSE),"Não encontrado") -> Não encontrado | F10: FIInfra
A11: IFRA11 | B11: ITAÚ FIF - CIC FIF INCEN EM INFRA RF CRED PRIV - R | C11: 34.633.510/0001-18 | D11: =IFERROR(VLOOKUP(A11,base_fiis_inv10!$A$1:$C$282,2,FALSE),"Não encontrado") -> Outro | E11: =IFERROR(VLOOKUP(A11,base_fiis_inv10!$A$1:$C$282,3,FALSE),"Não encontrado") -> Fundo de Infraestrutura (FI-Infra) | F11: FIInfra
A12: IFRI11 | B12: ITAÚ FIC FI INVEST FINAN INFRA CDI RF CRED PRIV | C12: 53.556.099/0001-79 | D12: =IFERROR(VLOOKUP(A12,base_fiis_inv10!$A$1:$C$282,2,FALSE),"Não encontrado") -> Outro | E12: =IFERROR(VLOOKUP(A12,base_fiis_inv10!$A$1:$C$282,3,FALSE),"Não encontrado") -> Fundo de Infraestrutura (FI-Infra) | F12: FIInfra
A13: INFB11 | B13: DRYS FDO INV EM COTAS DE FDO INC DE INV INFRA RF | C13: 54.810.341/0001-51 | D13: =IFERROR(VLOOKUP(A13,base_fiis_inv10!$A$1:$C$282,2,FALSE),"Não encontrado") -> Não encontrado | E13: =IFERROR(VLOOKUP(A13,base_fiis_inv10!$A$1:$C$282,3,FALSE),"Não encontrado") -> Não encontrado | F13: FIInfra
... A31: XPID11 | B31: XP FDO INV. COTAS FDO INC. INV. EM INFR. R. FIXA | C31: 37.404.867/0001-12 | D31: =IFERROR(VLOOKUP(A31,base_fiis_inv10!$A$1:$C$282,2,FALSE),"Não encontrado") -> Outro | E31: =IFERROR(VLOOKUP(A31,base_fiis_inv10!$A$1:$C$282,3,FALSE),"Não encontrado") -> Fundo de Infraestrutura (FI-Infra) | F31: FIInfra

Sheet base_fiis_inv10
A1: Ativos | B1: Tipo de Fundo | C1: Segmento
A2: RSPD11 | B2: Fundo de desenvolvimento | C2: Outros
A3: RELG11 | B3: Fundo de Tijolo | C3: Híbrido
A4: SNFZ11 | B4: Outro | C4: Fiagros
A5: HCHG11 | B5: Fundo de papel | C5: Outros
A6: ALZM11 | B6: Fundo de fundos | C6: Títulos e Valores Mobiliários
A7: NUIF11 | B7: Outro | C7: Fundo de Infraestrutura (FI-Infra)
A8: SMRE11 | B8: Outro | C8: Outros
A9: EQIR11 | B9: Outro | C9: Títulos e Valores Mobiliários
A10: CFII11 | B10: Fundo de desenvolvimento | C10: Híbrido
A11: IAAG11 | B11: Outro | C11: Fiagros
A12: LSAG11 | B12: Outro | C12: Fiagros
... A282: BTCI11 | B282: Fundo de papel | C282: Títulos e Valores Mobiliários

Sheet fonte
A1: https://maisretorno.com/lista-acoes/
A3: Copiei todas as paginas na mão e colei no excel de forma desestruturada.
A4: Depois com python eu tratei os dados e gerei esse arquivo.
A6: Manutençao:
A7: Se tiver algum ticker que não consta na lista, pegar infos na internet e preencher manualmente.
A8: Deixar separado cada tipo em uma aba mesmo pois essa será minha base manual e posso add cols caso eu queira. Além do que os dfs de posição serão separados também.
A10: ETF não puxei, eram 123 páginas.
A13: Base Investidor 10 - FIIs/FIAgros/FIInfras
A14: Também copiei na mão as 2 cols
A15: Quando for atualizar ticker, verificar também se existe na base do inv 10
A16: Puxa categorias com PROCV, qdo não acha: 'Não encontrado'
